Workbook

Sheet Historias de Usuario
B1: Desarrollo ágil: Pila de Producto (Product Backlog)
B4: Identificador (ID) de la Historia | C4: Enunciado de la Historia | D4: Alias | E4: Estado | F4: Puntos Valor | G4: Puntos Historia | H4: ROI | I4: Iteración (Sprint) | J4: Prioridad | K4: Comentarios
B5: US-17 | C5: Como usuario del sistema (profesor, secretaria, padre de familia o administrador), quiero iniciar sesión con mi cuenta y ver solo las opciones de mi rol, para que nadie más pueda ver o modificar las notas que me corresponden. | D5: Autenticación y Roles | E5: En proceso | F5: 13 | G5: 5 | H5: =ROUND(F5/G5,2) -> 2.6 | I5: Sprint 1 | J5: ALTA | K5: NUEVA (propuesta del análisis; requiere aprobación del docente). Base de todas las historias: sin ella no se cumple RNF-04 (solo el docente de la materia modifica notas) ni la métrica M09.
B6: US-18 | C6: Como secretaria, quiero registrar la gestión, sus trimestres, los cursos, las materias y los estudiantes, y asignar cada materia a su profesor, para que cada profesor trabaje solo con sus cursos y materias. | D6: Gestión Académica Base | E6: En proceso | F6: 13 | G6: 5 | H6: =ROUND(F6/G6,2) -> 2.6 | I6: Sprint 1 | J6: ALTA | K6: NUEVA (propuesta del análisis; requiere aprobación del docente). US-01 necesita que existan estudiantes, materias, periodos y la asignación profesor–materia.
B7: US-01 | C7: Como profesor, quiero registrar las calificaciones de cada estudiante por materia, actividad y periodo en un sistema único, para dejar de tener notas dispersas entre cuadernos, Excel y mensajes de WhatsApp. | D7: Registro Central de Notas | E7: En proceso | F7: 13 | G7: 5 | H7: =ROUND(F7/G7,2) -> 2.6 | I7: Sprint 1 | J7: ALTA | K7: Depende de US-17 y US-18. Módulo crítico del SQAP (TDD obligatorio).
B8: US-02 | C8: Como profesor, quiero que el sistema calcule automáticamente el promedio y la nota final de cada estudiante por periodo según la ponderación que yo defina para cada tipo de actividad, para evitar errores de cálculo manual y ahorrar horas al cierre de trimestre. | D8: Cálculo Automático de Promedios | E8: En proceso | F8: 13 | G8: 5 | H8: =ROUND(F8/G8,2) -> 2.6 | I8: Sprint 1 | J8: ALTA | K8: Depende de US-01 y US-18. Módulo crítico del SQAP (TDD, cobertura ≥ 90 %). Se adelanta al Sprint 1 porque es el núcleo del sistema y el mayor riesgo (R02). Importante: las ponderaciones no las decide el profesor; las fija el Ministerio de Educación por dimensión (RM 001/2026: Ser 10, Saber 45, Hacer 40, Autoevaluación 5). El profesor define las actividades dentro de cada dimensión (ver hoja Reglas MinEdu).
B9: US-04 | C9: Como profesor, quiero corregir una nota ya registrada y que el sistema guarde quién la cambió, cuándo y cuál era el valor anterior, para poder justificar cualquier corrección ante los padres o la dirección académica. | D9: Corrección Auditable de Notas | E9: En proceso | F9: 8 | G9: 3 | H9: =ROUND(F9/G9,2) -> 2.67 | I9: Sprint 2 | J9: ALTA | K9: Depende de US-01. Se propone como tercer módulo crítico del SQAP (cubre RNF-04).
B10: US-03 | C10: Como profesor, quiero consultar en cualquier momento el historial completo de notas de un estudiante a lo largo del año, para identificar su evolución académica sin tener que buscar en registros físicos anteriores. | D10: Historial Académico del Estudiante | E10: En proceso | F10: 10 | G10: 5 | H10: =ROUND(F10/G10,2) -> 2 | I10: Sprint 2 | J10: ALTA | K10: Depende de US-01.
B11: US-19 | C11: Como profesor, quiero registrar la asistencia de mis estudiantes en cada clase, para que el sistema calcule su porcentaje de asistencia sin llevarlo en un cuaderno aparte. | D11: Registro de Asistencia | E11: En proceso | F11: 8 | G11: 5 | H11: =ROUND(F11/G11,2) -> 1.6 | I11: Sprint 2 | J11: ALTA | K11: NUEVA (propuesta del análisis; requiere aprobación del docente). US-06 y US-07 muestran el porcentaje de asistencia, pero ninguna historia lo registraba. Depende de US-18.
B12: US-05 | C12: Como profesor, quiero importar las notas que ya tengo registradas en planillas Excel para migrarlas al sistema sin volver a digitarlas una por una, para que la adopción no me genere doble trabajo. | D12: Importación desde Excel | E12: En proceso | F12: 8 | G12: 5 | H12: =ROUND(F12/G12,2) -> 1.6 | I12: Sprint 2 | J12: MEDIA | K12: Depende de US-01. Las notas importadas pasan por la misma validación y auditoría que US-01 y US-04.
B13: US-10 | C13: Como secretaria, quiero ver qué profesores ya entregaron sus notas y cuáles faltan por curso, para hacer seguimiento antes del cierre del trimestre. | D13: Control de Entrega de Notas | E13: En proceso | F13: 5 | G13: 3 | H13: =ROUND(F13/G13,2) -> 1.67 | I13: Sprint 2 | J13: MEDIA | K13: Depende de US-01 y US-18. (Valores estimados: validar con el dueño del producto.)
B14: US-06 | C14: Como profesor, quiero ver en un solo panel el listado de estudiantes de mi curso con su promedio actual y su porcentaje de asistencia, para identificar de un vistazo quiénes están en riesgo académico antes del cierre de periodo. | D14: Panel de Riesgo Académico | E14: Planificada | F14: 10 | G14: 5 | H14: =ROUND(F14/G14,2) -> 2 | I14: Sprint 3 | J14: ALTA | K14: Depende de US-02 y US-19.
B15: US-07 | C15: Como profesor, quiero generar el boletín de calificaciones de cada estudiante con sus notas por materia, promedio final y porcentaje de asistencia en un PDF listo para entregar, para no armar el documento manualmente al cierre de cada periodo. | D15: Boletín de Notas en PDF | E15: Planificada | F15: 13 | G15: 8 | H15: =ROUND(F15/G15,2) -> 1.63 | I15: Sprint 3 | J15: MEDIA | K15: Depende de US-02, US-03 y US-19. Riesgo R05 / defecto CAL-001: generación en cola para cursos de más de 50 estudiantes.
B16: US-20 | C16: Como secretaria, quiero vincular la cuenta de cada padre de familia con sus hijos, para que cada padre vea únicamente la información de sus propios hijos. | D16: Vinculación Padre–Estudiante | E16: Planificada | F16: 5 | G16: 3 | H16: =ROUND(F16/G16,2) -> 1.67 | I16: Sprint 3 | J16: MEDIA | K16: NUEVA (propuesta del análisis; requiere aprobación del docente). US-11 y US-12 dicen "mi hijo", pero nada define qué hijo es de quién. Sin esto, un padre podría ver datos de otro estudiante (datos de menores).
... B20: US-12 | C20: Como padre de familia, quiero recibir una notificación cuando el boletín de mi hijo esté disponible, para enterarme a tiempo de sus resultados. | D20: Aviso de Boletín | E20: Planificada | F20: 3 | G20: 2 | H20: =ROUND(F20/G20,2) -> 1.5 | I20: Sprint 4 | J20: BAJA | K20: Depende de US-07, US-11 y US-20. Usa el mismo canal de notificación que US-08. (Valores estimados: validar con el dueño del producto.)
B21: US-16 | C21: Como secretaria, quiero registrar los pagos y ver un reporte de los estudiantes con mensualidades pendientes, para llevar el control sin tener que cobrar estudiante por estudiante. | D21: Control de Pagos | F21: 8 | G21: 5 | H21: =ROUND(F21/G21,2) -> 1.6 | I21: Release 2 (fuera de v1.0) | J21: MEDIA | K21: Propuesta: módulo de pagos fuera de la versión 1.0. No cabe en 4 sprints con 2 personas y los pagos elevan el nivel de integridad a 3 (IEEE 1012). Negociar con el docente. (Valores estimados: validar con el dueño del producto.)
B22: US-13 | C22: Como padre de familia, quiero ver el estado de las mensualidades de mi hijo (pagadas, pendientes y vencidas), para saber exactamente cuánto debo y hasta cuándo. | D22: Estado de Mensualidades | F22: 8 | G22: 3 | H22: =ROUND(F22/G22,2) -> 2.67 | I22: Release 2 (fuera de v1.0) | J22: MEDIA | K22: Depende de US-16. Módulo de pagos fuera de v1.0 (ver US-16). (Valores estimados: validar con el dueño del producto.)
B23: US-15 | C23: Como padre de familia, quiero recibir recordatorios antes del vencimiento de cada mensualidad, para no depender de que mi hijo me avise. | D23: Recordatorio de Pago | F23: 5 | G23: 3 | H23: =ROUND(F23/G23,2) -> 1.67 | I23: Release 2 (fuera de v1.0) | J23: BAJA | K23: Depende de US-13. Módulo de pagos fuera de v1.0 (ver US-16). (Valores estimados: validar con el dueño del producto.)
B24: US-14 | C24: Como padre de familia, quiero pagar las mensualidades en línea (QR o transferencia), para no tener que ir al colegio ni enviar el dinero con mi hijo. | D24: Pago en Línea | F24: 13 | G24: 13 | H24: =ROUND(F24/G24,2) -> 1 | I24: Release 2 (fuera de v1.0) | J24: MEDIA | K24: Depende de US-13. Integración con QR/transferencia: requiere proveedor de pagos y controles de seguridad de nivel 3. Fuera de v1.0 (ver US-16). (Valores estimados: validar con el dueño del producto.)
B26: Leyenda: | C26: Amarillo = historia nueva propuesta (falta aprobación del docente). Gris = fuera de la versión 1.0 (Estado vacío = identificada, sin iteración asignada, según el Instructivo). Orden: por sprint y luego por prioridad.

Sheet Plan de sprints
A1: Plan de 4 sprints de 1 semana — CalisFacu v1.0
A3: Velocidad supuesta del equipo (puntos de historia por sprint) | D3: 20 | E3: 2 integrantes. Con sprints de 1 semana, 20 puntos por semana es exigente: medir la velocidad real al cerrar la semana 1 y, si es menor, recortar empezando por las historias BAJA del Sprint 4 (US-08, US-12).
A4: Duración de cada sprint (semanas) | D4: 1 | E4: Plazo fijo del equipo: 4 semanas en total, un sprint por semana.
A6: Sprint | B6: Historias | C6: Puntos planificados | D6: Carga vs. velocidad | E6: Objetivo del sprint | F6: Actividades de calidad (SQAP) que cierran el sprint
A7: Sprint 1 | B7: US-17, US-18, US-01, US-02 | C7: =SUMIFS('Historias de Usuario'!$G$5:$G$24,'Historias de Usuario'!$I$5:$I$24,A7) -> 20 | D7: =IF(C7>1.1*$D$3,"Sobrecarga",IF(C7>=0.8*$D$3,"OK","Holgura")) -> OK | E7: Semana 1. Un profesor inicia sesión, registra notas de su materia y ve el promedio calculado correctamente. | F7: Días 1–2: revisión e inspección Fagan del SRS con el cliente; tabla de casos de prueba del cálculo según la RM 001/2026, firmada por el cliente (R02); inspección Fagan del SAD · Día 2: repositorio con develop y main protegidas, Husky y Jenkins Multibranch; staging con despliegue continuo y smoke test (ADR-0009) (ESLint + Prettier, Jest + cobertura, SonarQube Cloud, npm audit) · Día 5: auditoría de cierre del Sprint 1
A8: Sprint 2 | B8: US-04, US-03, US-19, US-05, US-10 | C8: =SUMIFS('Historias de Usuario'!$G$5:$G$24,'Historias de Usuario'!$I$5:$I$24,A8) -> 21 | D8: =IF(C8>1.1*$D$3,"Sobrecarga",IF(C8>=0.8*$D$3,"OK","Holgura")) -> OK | E8: Semana 2. Las notas se corrigen con auditoría, se importan desde Excel y se registra la asistencia. | F8: Día 1: revisión de diseño detallado de US-04 y US-05 · Primeros escenarios E2E de Cypress (Registrar calificación) · Día 5: auditoría de cierre del Sprint 2
A9: Sprint 3 | B9: US-06, US-07, US-20, US-11 | C9: =SUMIFS('Historias de Usuario'!$G$5:$G$24,'Historias de Usuario'!$I$5:$I$24,A9) -> 21 | D9: =IF(C9>1.1*$D$3,"Sobrecarga",IF(C9>=0.8*$D$3,"OK","Holgura")) -> OK | E9: Semana 3. El profesor genera el boletín en PDF y el padre lo consulta. | F9: Día 4: release candidate RC1 con E2E completo y prueba de carga JMeter (M03, M04) · Prueba de usabilidad con profesores nuevos · Día 5: auditoría de cierre del Sprint 3
A10: Sprint 4 | B10: US-09, US-08, US-12 | C10: =SUMIFS('Historias de Usuario'!$G$5:$G$24,'Historias de Usuario'!$I$5:$I$24,A10) -> 18 | D10: =IF(C10>1.1*$D$3,"Sobrecarga",IF(C10>=0.8*$D$3,"OK","Holgura")) -> OK | E10: Semana 4. La secretaria centraliza las notas del trimestre en el formato de la planilla oficial y los avisos automáticos funcionan. | F10: Día 3: RC2 con todas las métricas en verde · Día 4: pruebas de aceptación con el cliente (acta firmada) · Manual de usuario y manual técnico · Día 5: auditoría final del SQAP y release v1.0
A11: Release 2 (fuera de v1.0) | B11: US-16, US-13, US-15, US-14 | C11: =SUMIFS('Historias de Usuario'!$G$5:$G$24,'Historias de Usuario'!$I$5:$I$24,A11) -> 24 | E11: Módulo de pagos (propuesto para una versión posterior). | F11: Si se incluye: reevaluar el nivel de integridad a 3 y actualizar el SQAP antes de construir.
A12: Total v1.0 (Sprints 1 a 4) | C12: =SUM(C7:C10) -> 80 | D12: =IF(C12>4*$D$3,"No cabe en 4 sprints","Cabe en 4 sprints") -> Cabe en 4 sprints
A13: Total backlog completo | C13: =SUM('Historias de Usuario'!$G$5:$G$24) -> 104 | D13: =IF(C13>4*$D$3,"No cabe en 4 sprints","Cabe en 4 sprints") -> No cabe en 4 sprints
A16: Capacidad por persona (horas por semana) | D16: 30 | E16: Supuesto: ajustar a las horas reales que cada uno puede dedicar.
A18: Sprint | B18: Horas Lujan | C18: Horas Galvan | D18: Estado Lujan | E18: Estado Galvan
A19: Sprint 1 | B19: =SUMIFS('Tareas (Sprint Backlog)'!$H$5:$H$73,'Tareas (Sprint Backlog)'!$B$5:$B$73,A19,'Tareas (Sprint Backlog)'!$F$5:$F$73,"Lujan") -> 56 | C19: =SUMIFS('Tareas (Sprint Backlog)'!$H$5:$H$73,'Tareas (Sprint Backlog)'!$B$5:$B$73,A19,'Tareas (Sprint Backlog)'!$F$5:$F$73,"Galvan") -> 22 | D19: =IF(B19>$D$16,"Sobrecarga: "&TEXT(B19-$D$16,"0")&" h","OK") -> Sobrecarga: 26 h | E19: =IF(C19>$D$16,"Sobrecarga: "&TEXT(C19-$D$16,"0")&" h","OK") -> OK
A20: Sprint 2 | B20: =SUMIFS('Tareas (Sprint Backlog)'!$H$5:$H$73,'Tareas (Sprint Backlog)'!$B$5:$B$73,A20,'Tareas (Sprint Backlog)'!$F$5:$F$73,"Lujan") -> 17 | C20: =SUMIFS('Tareas (Sprint Backlog)'!$H$5:$H$73,'Tareas (Sprint Backlog)'!$B$5:$B$73,A20,'Tareas (Sprint Backlog)'!$F$5:$F$73,"Galvan") -> 21 | D20: =IF(B20>$D$16,"Sobrecarga: "&TEXT(B20-$D$16,"0")&" h","OK") -> OK | E20: =IF(C20>$D$16,"Sobrecarga: "&TEXT(C20-$D$16,"0")&" h","OK") -> OK
A21: Sprint 3 | B21: =SUMIFS('Tareas (Sprint Backlog)'!$H$5:$H$73,'Tareas (Sprint Backlog)'!$B$5:$B$73,A21,'Tareas (Sprint Backlog)'!$F$5:$F$73,"Lujan") -> 18 | C21: =SUMIFS('Tareas (Sprint Backlog)'!$H$5:$H$73,'Tareas (Sprint Backlog)'!$B$5:$B$73,A21,'Tareas (Sprint Backlog)'!$F$5:$F$73,"Galvan") -> 20 | D21: =IF(B21>$D$16,"Sobrecarga: "&TEXT(B21-$D$16,"0")&" h","OK") -> OK | E21: =IF(C21>$D$16,"Sobrecarga: "&TEXT(C21-$D$16,"0")&" h","OK") -> OK
A22: Sprint 4 | B22: =SUMIFS('Tareas (Sprint Backlog)'!$H$5:$H$73,'Tareas (Sprint Backlog)'!$B$5:$B$73,A22,'Tareas (Sprint Backlog)'!$F$5:$F$73,"Lujan") -> 17 | C22: =SUMIFS('Tareas (Sprint Backlog)'!$H$5:$H$73,'Tareas (Sprint Backlog)'!$B$5:$B$73,A22,'Tareas (Sprint Backlog)'!$F$5:$F$73,"Galvan") -> 15 | D22: =IF(B22>$D$16,"Sobrecarga: "&TEXT(B22-$D$16,"0")&" h","OK") -> OK | E22: =IF(C22>$D$16,"Sobrecarga: "&TEXT(C22-$D$16,"0")&" h","OK") -> OK

Sheet Tareas (Sprint Backlog)
A1: Pila del sprint: tareas por historia
A2: Revisor = el otro integrante (nadie aprueba su propio PR). "Backend (crítico)" = módulos críticos del SQAP: los programa Lujan y los aprueba Galvan, que no programa módulos críticos. Horas = estimación inicial; ajustar en la planificación de cada sprint.
A4: ID | B4: Sprint | C4: Historia | D4: Tarea | E4: Tipo | F4: Responsable | G4: Revisor | H4: Horas est. | I4: Estado | J4: Criterio / métrica
A5: T-001 | B5: Sprint 1 | C5: Calidad | D5: Inspección Fagan del SRS con el cliente (moderador y escriba); acta en docs/actas/ | E5: Revisión | F5: Galvan | G5: Lujan | H5: 3 | I5: Por hacer | J5: SQAP Sec. 6
A6: T-002 | B6: Sprint 1 | C6: Calidad | D6: Redactar el SAD: modelo de datos PostgreSQL, módulos NestJS y ADRs del stack | E6: Diseño | F6: Lujan | G6: Galvan | H6: 3 | I6: En revisión | J6: SQAP Sec. 4
A7: T-003 | B7: Sprint 1 | C7: Calidad | D7: Inspección Fagan del SAD con un inspector de otro equipo; acta | E7: Revisión | F7: Galvan | G7: Lujan | H7: 2 | I7: Por hacer | J7: SQAP Sec. 6
A8: T-004 | B8: Sprint 1 | C8: Calidad | D8: Tabla de casos de prueba del cálculo (RM 001/2026, hoja Reglas MinEdu) firmada por el cliente; resolver los ❓ | E8: Requerimientos | F8: Lujan | G8: Galvan | H8: 2 | I8: En proceso | J8: R02
A9: T-005 | B9: Sprint 1 | C9: Infra | D9: Monorepo: api (NestJS + TypeORM) y web (React + Vite + TypeScript); Docker Compose con PostgreSQL | E9: Infra | F9: Galvan | G9: Lujan | H9: 3 | I9: En revisión
A10: T-006 | B10: Sprint 1 | C10: Infra | D10: ESLint + Prettier; Husky + lint-staged + commitlint (Conventional Commits) | E10: Infra | F10: Galvan | G10: Lujan | H10: 2 | I10: En revisión | J10: Práctica 8
A11: T-007 | B11: Sprint 1 | C11: Infra | D11: Jenkins en Docker (jenkins/) y job Multibranch: lint, pruebas con umbral de cobertura en Jest, build; PostgreSQL de CI | E11: Infra | F11: Galvan | G11: Lujan | H11: 4 | I11: En revisión | J11: M01, M05, M06
A12: T-008 | B12: Sprint 1 | C12: Infra | D12: Proteger develop y main (PR + check de Jenkins) y npm audit en el CI | E12: Infra | F12: Galvan | G12: Lujan | H12: 1 | I12: Por hacer | J12: M08
A13: T-009 | B13: Sprint 1 | C13: US-17 | D13: Entidad Usuario y Rol con migración de TypeORM; seed de usuarios sintéticos | E13: Backend | F13: Lujan | G13: Galvan | H13: 2 | I13: En revisión | J13: R07
A14: T-010 | B14: Sprint 1 | C14: US-17 | D14: Autenticación JWT con Passport, contraseñas con argon2, bloqueo tras 5 intentos y expiración de sesión | E14: Backend | F14: Lujan | G14: Galvan | H14: 4 | I14: En revisión | J14: US-17 CA 1, 3, 4
A15: T-011 | B15: Sprint 1 | C15: US-17 | D15: Guard de roles y pruebas que exigen HTTP 403 en rutas de escritura de notas | E15: Backend | F15: Lujan | G15: Galvan | H15: 3 | I15: En revisión | J15: M09
A16: T-012 | B16: Sprint 1 | C16: US-17 | D16: Pantalla de inicio de sesión y menú por rol | E16: Frontend | F16: Lujan | G16: Galvan | H16: 3 | I16: En revisión | J16: US-17 CA 1
A17: T-013 | B17: Sprint 1 | C17: US-17 | D17: E2E Cypress: inicio de sesión de cada rol | E17: Prueba | F17: Lujan | G17: Galvan | H17: 2 | I17: En revisión | J17: M02
A18: T-014 | B18: Sprint 1 | C18: US-18 | D18: Modelo académico: gestión, trimestre, unidad educativa (código SIE, nivel, año, paralelo), curso, materia, estudiante, asignación profesor–materia; migraciones y seed | E18: Backend | F18: Lujan | G18: Galvan | H18: 4 | I18: En revisión | J18: US-18 CA 1–5
A19: T-015 | B19: Sprint 1 | C19: US-18 | D19: Configuración de dimensiones por gestión (suman 100; bloqueadas si hay notas) — TDD | E19: Backend (crítico) | F19: Lujan | G19: Galvan | H19: 3 | I19: En revisión | J19: US-18 CA 6–7, RNF-01
A20: T-016 | B20: Sprint 1 | C20: US-18 | D20: API CRUD de la secretaria: cursos, materias, estudiantes y asignaciones | E20: Backend | F20: Lujan | G20: Galvan | H20: 4 | I20: En revisión | J20: US-18 CA 1–3
A21: T-017 | B21: Sprint 1 | C21: US-18 | D21: Pantallas de la secretaria para la gestión académica | E21: Frontend | F21: Lujan | G21: Galvan | H21: 4 | I21: En revisión | J21: US-18
... A73: T-069 | B73: Sprint 4 | C73: Calidad | D73: Release v1.0: PR develop → main, etiqueta v1.0.0, CHANGELOG y despliegue a producción | E73: Infra | F73: Lujan | G73: Galvan | H73: 1 | I73: Por hacer | J73: SQAP Sec. 10

Sheet DoR y DoD
A1: Definition of Ready y Definition of Done
A3: Definition of Ready: una historia entra al sprint solo si… | B3: Cómo se comprueba
A4: Tiene enunciado Como / Quiero / Para, alias y puntos de historia. | B4: Hoja Historias de Usuario
A5: Tiene criterios de aceptación en formato Dado / Cuando / Entonces. | B5: Hoja Criterios de aceptación
A6: No le queda ningún ❓ sin resolver. | B6: Respuesta del cliente anotada en la hoja
A7: Sus dependencias están en un sprint anterior o primero en el mismo sprint. | B7: Columna Comentarios
A8: Está dividida en tareas con responsable, revisor y horas. | B8: Hoja Tareas (Sprint Backlog)
A9: Si es un módulo crítico, su diseño detallado fue revisado. | B9: Acta en docs/actas/
A11: Definition of Done: una historia está Hecha solo si… | B11: Cómo se comprueba
A12: Todos sus criterios de aceptación tienen una prueba automatizada que pasa. | B12: Test Result del build de Jenkins
A13: El pipeline está sano: lint, pruebas, cobertura, Quality Gate y auditoría de dependencias en verde. | B13: Build de Jenkins del commit en develop (ADR-0008)
A14: Cobertura ≥ 80 % en código nuevo y ≥ 90 % en el módulo de cálculo, exigida por la herramienta. | B14: coverageThreshold de Jest y Quality Gate
A15: El otro integrante revisó sus commits en develop; nadie aprueba su propio código. | B15: Comentarios de revisión en los commits de GitHub
... A18: La documentación que cambió (SRS, SAD, manual) se actualizó en el mismo PR. | B18: Diff del PR

Sheet Criterios de aceptación
A1: Criterios de aceptación (formato Dado / Cuando / Entonces)
A2: Cada criterio es una prueba: Jest (unitaria o e2e con Supertest) o Cypress (E2E). ❓ = regla que el cliente debe confirmar antes de iniciar la historia.
A4: ID | B4: Alias | C4: N.º | D4: Criterio de aceptación | E4: Prueba que lo verifica | F4: Vínculo SQAP
A5: US-17 | B5: Autenticación y Roles | C5: 1 | D5: Dado un usuario con credenciales válidas, cuando inicia sesión, entonces entra a la pantalla de inicio de su rol y solo ve las opciones de ese rol. | E5: Cypress | F5: RNF-04
A6: US-17 | B6: Autenticación y Roles | C6: 2 | D6: Dado un usuario sin rol Profesor, cuando envía una petición a cualquier ruta de escritura de notas, entonces recibe HTTP 403 y no se modifica ningún dato. | E6: Jest + Supertest (e2e) | F6: M09
A7: US-17 | B7: Autenticación y Roles | C7: 3 | D7: Dado 5 intentos fallidos seguidos con la misma cuenta, cuando intenta un sexto, entonces el sistema bloquea el inicio de sesión durante 15 minutos. | E7: Jest + Supertest (e2e) | F7: RNF-04
A8: US-17 | B8: Autenticación y Roles | C8: 4 | D8: Dado un usuario autenticado sin actividad, cuando pasan 30 minutos, entonces la sesión expira y debe iniciar sesión otra vez. | E8: Jest + Supertest (e2e) | F8: RNF-04
A9: US-18 | B9: Gestión Académica Base | C9: 1 | D9: Dado el rol Secretaria, cuando registra un curso con paralelo y gestión, entonces el curso queda disponible para asignarle materias y estudiantes. | E9: Cypress
A10: US-18 | B10: Gestión Académica Base | C10: 2 | D10: Dado un profesor asignado a dos materias, cuando inicia sesión, entonces ve solo esas dos materias. | E10: Jest + Supertest (e2e) | F10: RNF-04
A11: US-18 | B11: Gestión Académica Base | C11: 3 | D11: Dado un estudiante inscrito en un curso de la gestión, cuando se lo intenta inscribir en otro curso de la misma gestión, entonces el sistema lo rechaza con un mensaje. | E11: Jest (unitaria)
A12: US-18 | B12: Gestión Académica Base | C12: 4 | D12: Dado un trimestre marcado como cerrado, cuando un profesor intenta registrar o corregir una nota en él, entonces el sistema lo impide. | E12: Jest + Supertest (e2e) | F12: RNF-04
A13: US-18 | B13: Gestión Académica Base | C13: 5 | D13: Dado el registro de la unidad educativa, cuando se guarda, entonces incluye nombre, código SIE, nivel (Inicial, Primaria o Secundaria), año de escolaridad y paralelo, que luego aparecen en boletines y centralizadores. | E13: Jest + Supertest (e2e)
A14: US-18 | B14: Gestión Académica Base | C14: 6 | D14: Dado el rol Administrador, cuando configura la gestión, entonces registra las dimensiones de evaluación y su puntaje máximo según la resolución vigente (2026: Ser 10, Saber 45, Hacer 40, Autoevaluación 5) y el sistema exige que sumen 100. | E14: Jest (unitaria) | F14: RNF-01
A15: US-18 | B15: Gestión Académica Base | C15: 7 | D15: Dado un trimestre de la gestión que ya tiene notas registradas, cuando alguien intenta cambiar los puntajes de las dimensiones, entonces el sistema lo impide. | E15: Jest + Supertest (e2e) | F15: RNF-04
A16: US-01 | B16: Registro Central de Notas | C16: 1 | D16: Dado un profesor en una materia asignada y un trimestre abierto, cuando registra la nota de una actividad dentro de una dimensión (Ser, Saber, Hacer o Autoevaluación) en la escala de 1 a 100, entonces la nota se guarda y aparece en la planilla. | E16: Cypress | F16: M02
A17: US-01 | B17: Registro Central de Notas | C17: 2 | D17: Dado un valor fuera de 1 a 100 (no se admite 0; una actividad no presentada se registra con 1, decisión D1), vacío o no numérico, cuando intenta guardar, entonces aparece un mensaje junto al campo y no se guarda nada. | E17: Jest (unitaria) | F17: M01
A18: US-01 | B18: Registro Central de Notas | C18: 3 | D18: Dado una planilla con las notas de todos los estudiantes de la materia (hasta 60), cuando guarda, entonces se guardan todas o ninguna (una sola transacción). | E18: Jest + Supertest (e2e) | F18: RNF-02
A19: US-01 | B19: Registro Central de Notas | C19: 4 | D19: Dado 100 profesores registrando notas al mismo tiempo durante 10 minutos, cuando se mide en staging, entonces la tasa de error es menor que 1 %. | E19: JMeter | F19: M04
A20: US-02 | B20: Cálculo Automático de Promedios | C20: 1 | D20: Dado las notas de las actividades de una dimensión, cuando se calcula, entonces el puntaje de la dimensión es el promedio de esas notas × (puntaje máximo de la dimensión / 100). Ej.: Saber con promedio 80 → 80 × 45/100 = 36 puntos. | E20: Jest (unitaria, TDD) | F20: M01, M06
A21: US-02 | B21: Cálculo Automático de Promedios | C21: 2 | D21: Dado los puntajes de Ser, Saber, Hacer y Autoevaluación, cuando se calcula la nota del trimestre, entonces es la suma de los cuatro, redondeada al entero más cercano (0,5 hacia arriba), en la escala de 1 a 100. | E21: Jest (unitaria, TDD) | F21: M01, RNF-01
A22: US-02 | B22: Cálculo Automático de Promedios | C22: 3 | D22: Dado una nota trimestral de 50,5 antes de redondear, cuando se redondea, entonces es 51 y el estudiante figura como aprobado; con 50,4 es 50 y figura como reprobado (nota mínima de aprobación: 51). | E22: Jest (unitaria, TDD) | F22: RNF-01, R02
A23: US-02 | B23: Cálculo Automático de Promedios | C23: 4 | D23: Dado las notas de los tres trimestres, cuando se calcula la nota anual de la materia, entonces es el promedio de los tres trimestres redondeado al entero, 0,5 hacia arriba (decisiones D2 y D3). | E23: Jest (unitaria, TDD) | F23: RNF-01, R02
A24: US-02 | B24: Cálculo Automático de Promedios | C24: 5 | D24: Dado la tabla de casos de prueba firmada por el cliente (semilla en la hoja Reglas MinEdu), cuando corre la suite, entonces el 100 % de los casos da el resultado esperado. | E24: Jest (unitaria, TDD) | F24: M01, R02
A25: US-02 | B25: Cálculo Automático de Promedios | C25: 6 | D25: Dado una dimensión que todavía no tiene actividades con nota, cuando se calcula la nota parcial del trimestre, entonces la nota trimestral se muestra como "pendiente" e indica qué dimensiones faltan (decisión D4). | E25: Jest (unitaria, TDD) | F25: R02
... A30: US-03 | B30: Historial Académico del Estudiante | C30: 2 | D30: Dado un estudiante que no cursa ninguna materia del profesor, cuando el profesor intenta abrir su historial, entonces recibe HTTP 403. | E30: Jest + Supertest (e2e) | F30: M09
A31: US-19 | B31: Registro de Asistencia | C31: 1 | D31: Dado una clase de su materia, cuando el profesor marca a cada estudiante como presente, ausente o con licencia, entonces se guarda la asistencia de esa fecha. | E31: Cypress
A32: US-19 | B32: Registro de Asistencia | C32: 2 | D32: Dado las asistencias registradas, cuando se calcula el porcentaje, entonces es (presentes + licencias) / clases dictadas × 100, redondeado a un decimal (decisión D5). | E32: Jest (unitaria)
A33: US-19 | B33: Registro de Asistencia | C33: 3 | D33: Dado una fecha futura, cuando el profesor intenta registrar asistencia, entonces el sistema lo impide. | E33: Jest (unitaria)
A34: US-05 | B34: Importación desde Excel | C34: 1 | D34: Dado un archivo .xlsx con la plantilla del sistema, cuando el profesor lo sube, entonces ve una vista previa con las filas válidas y las filas con error antes de confirmar. | E34: Cypress
A35: US-05 | B35: Importación desde Excel | C35: 2 | D35: Dado una fila con un estudiante que no existe o una nota fuera de 0 a 100, cuando se importa, entonces esa fila se rechaza con su motivo y no se guarda. | E35: Jest + Supertest (e2e) | F35: M01
A36: US-05 | B36: Importación desde Excel | C36: 3 | D36: Dado una importación confirmada, cuando termina, entonces cada nota importada queda en la auditoría con origen "importación". | E36: Jest + Supertest (e2e) | F36: RNF-04
A37: US-10 | B37: Control de Entrega de Notas | C37: 1 | D37: Dado un trimestre en curso, cuando la secretaria abre el control, entonces ve por curso cada materia con su profesor y su estado Entregado o Pendiente. | E37: Cypress
A38: US-10 | B38: Control de Entrega de Notas | C38: 2 | D38: Dado una materia, cuando el profesor la marca como entregada, entonces solo se acepta si todos los estudiantes tienen nota en todas las actividades. | E38: Jest (unitaria)
A39: US-06 | B39: Panel de Riesgo Académico | C39: 1 | D39: Dado un curso del profesor, cuando abre el panel, entonces ve a cada estudiante con su promedio actual y su porcentaje de asistencia. | E39: Cypress
A40: US-06 | B40: Panel de Riesgo Académico | C40: 2 | D40: Dado un estudiante con promedio menor que 51 o asistencia menor que 80 % (umbral configurable por gestión, decisión D6), cuando se muestra el panel, entonces aparece marcado como "en riesgo". | E40: Jest (unitaria) | F40: RNF-01
A41: US-07 | B41: Boletín de Notas en PDF | C41: 1 | D41: Dado un estudiante, cuando el profesor genera su boletín, entonces el PDF muestra la unidad educativa, el código SIE, el nivel, el año de escolaridad y el paralelo, y por cada materia la nota de cada trimestre, la nota anual y el porcentaje de asistencia, iguales a los que muestra el sistema. | E41: Jest + Supertest (e2e) + Cypress | F41: M02
A42: US-07 | B42: Boletín de Notas en PDF | C42: 2 | D42: Dado 100 usuarios concurrentes durante 10 minutos en staging, cuando se genera el boletín de un estudiante, entonces el p95 es ≤ 2000 ms y la tasa de error < 1 %. | E42: JMeter | F42: M03, RNF-03
A43: US-07 | B43: Boletín de Notas en PDF | C43: 3 | D43: Dado un curso de más de 50 estudiantes, cuando se generan todos los boletines, entonces se procesan en una cola y el profesor recibe un aviso al terminar. | E43: Jest + Supertest (e2e) | F43: R05, CAL-001
A44: US-20 | B44: Vinculación Padre–Estudiante | C44: 1 | D44: Dado la secretaria, cuando vincula una cuenta de padre con uno o más estudiantes, entonces el padre ve solo a esos estudiantes. | E44: Cypress | F44: RNF-04
A45: US-20 | B45: Vinculación Padre–Estudiante | C45: 2 | D45: Dado un padre, cuando intenta ver los datos de un estudiante no vinculado (por ejemplo, cambiando el ID en la URL), entonces recibe HTTP 403. | E45: Jest + Supertest (e2e) | F45: RNF-04
...

Sheet Reglas MinEdu
A1: Sistema de evaluación del Ministerio de Educación (Subsistema de Educación Regular)
A2: Reglas que el cálculo de US-02 debe implementar. Las celdas amarillas son parámetros por gestión: se configuran en el sistema (US-18), no se programan fijos.
A4: Regla | B4: Valor 2026 | C4: Fuente | D4: Estado
A5: Periodos de evaluación | B5: 3 trimestres | C5: Reglamento de evaluación RM 0190/2024 (evaluación al cierre del 1.er, 2.º y 3.er trimestre) | D5: Confirmado
A6: Escala de calificación | B6: 1 a 100 (sin 0) | C6: Ministerio de Educación, vigente desde 2013 | D6: Decidido (D1)
A7: Nota mínima de aprobación | B7: 51 | C7: Ministerio de Educación, vigente desde 2013 | D7: Confirmado
A8: Dimensión Ser (puntaje máximo) | B8: 10 | C8: RM 001/2026 (5 de enero de 2026). Absorbe a la antigua dimensión Decidir. | D8: Confirmado
A9: Dimensión Saber (puntaje máximo) | B9: 45 | C9: RM 001/2026 | D9: Confirmado
A10: Dimensión Hacer (puntaje máximo) | B10: 40 | C10: RM 001/2026 | D10: Confirmado
A11: Autoevaluación (puntaje máximo) | B11: 5 | C11: RM 001/2026 | D11: Confirmado
A12: Nota anual de la materia | B12: Promedio de los 3 trimestres | C12: Práctica habitual; no se encontró el texto oficial | D12: Decidido (D3)
A13: Suma de dimensiones (debe ser 100) | B13: =SUM(B8:B11) -> 100 | C13: =IF(B13=100,"OK","Las dimensiones no suman 100") -> OK | D13: Confirmado
A15: Casos de ejemplo del cálculo (semilla de la tabla que firma el cliente, riesgo R02)
A16: Caso | B16: Prom. Ser (1-100) | C16: Prom. Saber (1-100) | D16: Prom. Hacer (1-100) | E16: Prom. Autoev. (1-100) | F16: Puntos Ser | G16: Puntos Saber | H16: Puntos Hacer | I16: Puntos Autoev. | J16: Nota sin redondear | K16: Nota trimestral | L16: Resultado
A17: Caso típico | B17: 80 | C17: 80 | D17: 80 | E17: 100 | F17: =B17*$B$8/100 -> 8 | G17: =C17*$B$9/100 -> 36 | H17: =D17*$B$10/100 -> 32 | I17: =E17*$B$11/100 -> 5 | J17: =SUM(F17:I17) -> 81 | K17: =ROUND(J17,0) -> 81 | L17: =IF(K17>=$B$7,"Aprueba","Reprueba") -> Aprueba
A18: Frontera: 50,5 se redondea a 51 (aprueba) | B18: 100 | C18: 50 | D18: 40 | E18: 40 | F18: =B18*$B$8/100 -> 10 | G18: =C18*$B$9/100 -> 22.5 | H18: =D18*$B$10/100 -> 16 | I18: =E18*$B$11/100 -> 2 | J18: =SUM(F18:I18) -> 50.5 | K18: =ROUND(J18,0) -> 51 | L18: =IF(K18>=$B$7,"Aprueba","Reprueba") -> Aprueba
A19: Frontera: 50,4 se redondea a 50 (reprueba) | B19: 80 | C19: 52 | D19: 40 | E19: 60 | F19: =B19*$B$8/100 -> 8 | G19: =C19*$B$9/100 -> 23.4 | H19: =D19*$B$10/100 -> 16 | I19: =E19*$B$11/100 -> 3 | J19: =SUM(F19:I19) -> 50.4 | K19: =ROUND(J19,0) -> 50 | L19: =IF(K19>=$B$7,"Aprueba","Reprueba") -> Reprueba
A20: Todo al máximo | B20: 100 | C20: 100 | D20: 100 | E20: 100 | F20: =B20*$B$8/100 -> 10 | G20: =C20*$B$9/100 -> 45 | H20: =D20*$B$10/100 -> 40 | I20: =E20*$B$11/100 -> 5 | J20: =SUM(F20:I20) -> 100 | K20: =ROUND(J20,0) -> 100 | L20: =IF(K20>=$B$7,"Aprueba","Reprueba") -> Aprueba
A21: Todo al mínimo de la escala | B21: 1 | C21: 1 | D21: 1 | E21: 1 | F21: =B21*$B$8/100 -> 0.1 | G21: =C21*$B$9/100 -> 0.45 | H21: =D21*$B$10/100 -> 0.4 | I21: =E21*$B$11/100 -> 0.05 | J21: =SUM(F21:I21) -> 1 | K21: =ROUND(J21,0) -> 1 | L21: =IF(K21>=$B$7,"Aprueba","Reprueba") -> Reprueba
A23: Fuentes: RM 001/2026 (minedu.gob.bo, 5 de enero de 2026; Red Uno y Urgente.bo, enero 2026); reglamento RM 0190/2024 (El Diario, 29 de marzo de 2024); escala 1 a 100 y aprobación con 51 (eju.tv, noviembre de 2012). Verificar contra el texto oficial antes de firmar la tabla.

Sheet Hallazgos
A1: Hallazgos de la revisión del backlog
A3: N.º | B3: Hallazgo | C3: Dónde | D3: Por qué importa | E3: Qué se hizo en esta versión
A4: 1 | B4: No hay historia de inicio de sesión ni de roles. | C4: Todo el backlog | D4: RNF-04 y la métrica M09 dependen de que existan roles; sin esto no hay forma de que "solo el docente modifique sus notas". | E4: Se propone US-17 (Sprint 1).
A5: 2 | B5: No hay historia para registrar cursos, materias, estudiantes, trimestres ni la asignación profesor–materia. | C5: Todo el backlog | D5: US-01 no se puede construir sin esos datos base. | E5: Se propone US-18 (Sprint 1).
A6: 3 | B6: Ninguna historia registra la asistencia. | C6: US-06, US-07 | D6: Ambas muestran el porcentaje de asistencia, que nadie registra. | E6: Se propone US-19 (Sprint 2).
A7: 4 | B7: Nada define qué padre ve a qué estudiante. | C7: US-11, US-12, US-13 | D7: Son datos de menores de edad: un padre podría ver la información de otro estudiante. | E7: Se propone US-20 (Sprint 3).
A8: 5 | B8: Las historias no tienen criterios de aceptación. | C8: Todas | D8: El SQAP (Sección 7) los exige como criterio de entrada; sin ellos no hay pruebas que escribir ni forma de decir "Hecho". | E8: Nueva hoja Criterios de aceptación.
A9: 6 | B9: El backlog estaba ordenado por ROI ascendente. | C9: Hoja Historias de Usuario | D9: Un product backlog se ordena por prioridad: lo más importante arriba. | E9: Ordenado por sprint y luego por prioridad.
A10: 7 | B10: El plan tenía 8 sprints; el equipo trabaja en 4. | C10: Columna Iteración | D10: Con 2 personas, el backlog completo (incluidas las historias nuevas) no cabe en 4 sprints. | E10: Re-planificado en 4 sprints; el módulo de pagos se propone para una versión posterior (ver hoja Plan de sprints).
A11: 8 | B11: El módulo de pagos eleva el nivel de integridad. | C11: US-13 a US-16 | D11: Según IEEE 1012 y la guía de la Práctica 7, pagos y datos personales sensibles son nivel 3; exigiría un SQAP más estricto. | E11: Fuera de v1.0, a negociar con el docente.
A12: 9 | B12: Reglas de negocio sin definir. | C12: US-02, US-06, US-19 | D12: Redondeo, actividades sin notas, licencias en la asistencia y umbral de riesgo no están escritos; es el riesgo R02 del SQAP. | E12: Marcadas con ❓ en los criterios; validar con el cliente en la semana 1.
A13: 10 | B13: Canal de notificación sin definir. | C13: US-08, US-12, US-15 | D13: No se puede estimar ni probar una alerta sin saber si es correo, aviso en el sistema o WhatsApp. | E13: Propuesta: correo + aviso en el sistema.
A14: 11 | B14: Escala de Puntos Valor mixta (10 no es de Fibonacci). | C14: US-03, US-06 | D14: Mezclar escalas hace que el ROI compare cosas distintas. | E14: Se dejó igual (backlog aprobado); se sugiere usar 1, 2, 3, 5, 8, 13.
A15: 12 | B15: Valores marcados "(Valores estimados)". | C15: Varias historias | D15: No están validados con el dueño del producto; el ROI y la prioridad pueden cambiar. | E15: Se mantiene la nota; validar en la revisión del backlog del Sprint 1.
... A21: 18 | B21: El plazo es de 4 semanas: cada sprint dura 1 semana. | C21: Plan de sprints | D21: 20 puntos por semana con 2 personas es exigente; si la velocidad real es menor, no se termina el Sprint 4. | E21: Duración = 1 semana; regla de recorte: primero US-08 y US-12 (prioridad BAJA).

Sheet Instructivo
B1: Pila de Producto (Product Backlog): Instructivo
B4: Columna | C4: Instrucciones
B5: Identificador (ID) de la Historia | C5: Código que identifica a la historia de forma unívoca, una vez asignado, no debe ser re-usado en otra historia, ni siquiera si la historia es descartada. El código identifica la historia en otros documentos, como por ejemplo la plantilla de historias de usuario.
B6: Enunciado de la Historia | C6: Nombre de la historia, el cual debe ser el mismo que se utiliza en otros documentos. Se puede utilizar el formato siguiente: Como [Rol], Quiero [Descripción de la Funcionalidad], para [Razón o Resultado]
B7: Alias | C7: Título de la historia alternativo a la descripción, que servirá para identificar más fácilmente la historia sin tener que repetir todo su enunciado. Se puede utilizar por ejemplo el nombre de la funcionalidad o requerimiento que se pretende desarrollar.
B8: Estado | C8: Identifica los posibles estados de la historia durante su ciclo de vida: - Vacío: La historia fue identifica pero aún no ha sido asignada a una iteración. - Planificada: La historia fue asignada a una iteración y aún no ha comenzado su ejecución. Puede tener este estado incluyendo en la iteración donde está planificado ejecutarla (pero que aún no ha comenzado). - En Proceso: La historia fue seleccionada por el equipo y está en proceso de desarrollo (en ejecución). - Hecho (Donde): La historia fue desarrollada. Es importante clarificar la definición de “Hecho” con el equipo de trabajo. “Hecho” no sólo incluye el desarrollo sino la integración y pruebas integrales del Software. Una historia hecha puede presentarse al dueño de producto para sus pruebas de aceptación. - Descartada: Se determinó que la historia ya no es relevante, su contenido se incluyó en otro grupo de historias o fue cancelada.
B9: Puntos Valor | C9: Medida del Valor para el dueño del producto
B10: Puntos Historia (Esfuerzo) | C10: Medida del esfuerzo (tamaño) que implica desarrollar la historia, existen distintos métodos para medirlo, un ejemplo es los “puntos de historia” una medida de complejidad no necesariamente relacionado con jornadas o días. Otra forma de medirlo es con días o jornadas ideales.
B11: ROI | C11: Retorno de la inversion PuntosValor /Puntos Historia , sirve para priorizar el desarrollo
B12: Iteración (Sprint) | C12: Iteración o Sprint al que se asigna la historia. Esta asignación puede cambiar en cada iteración donde se haga la revisión de la pila de producto (ProductBacklogReview), según las prioridades indicadas por el dueño de producto. Por medio de este campo se puede crear un “Plan de Salidas a Productivo” (Release Plan).
B13: Prioridad | C13: Siguiendo el marco de trabajo ágil y Scrum, se le deben asignar prioridades a las historias, según las instrucciones del dueño de producto (ProductOwner). De esta forma pueden ordenarse. Las historias de mayor prioridad deben ser las que agregan más valor al negocio, y deben ser originadas en sus necesidades.
B14: Comentarios | C14: Comentarios o detalles relacionadas que expliquen la historia. Para definiciones de mayor longitud deben usarse documentos externos, por ejemplo la plantilla de historias de usuario.
